<?xml version="0.0" ?>
<robot name="jackal">
	<link name="chassis_link">
		<inertial>
			<!-- Center of mass -->
			<origin rpy="0 0 0" xyz="0.012  0.002 0.067"/>
			<mass value="16.523"/>
			<!-- Moments of inertia: ( chassis without wheels ) -->
			<inertia ixx="0.3136" ixy="-0.0008" ixz="0.0164" iyy="0.3922" iyz="-0.0009" izz="0.4485"/>
		</inertial>

        <visual>
			<origin rpy="1.57079632679 0.0 1.57079632679" xyz="0 0 -0.0655"/>
            <geometry>
				<mesh filename="meshes/jackal-base.stl" scale="1.00000 1.00000 1.00000"/>
            </geometry>
			<material name="dark_grey"/>
        </visual>

		<collision>
			<origin xyz="0 0 0.092"/>
			<geometry>
				<box size="0.42 0.31 0.184"/>
			</geometry>
		</collision>
	</link>

	<link name="front_left_wheel_link">
		<visual>
			<origin rpy="1.57079632679 0 0" xyz="0 0 0"/>
			<geometry>
				<mesh filename="meshes/jackal-wheel.stl"/>
			</geometry>
			<material name="black"/>
		</visual>
	</link>

	<joint name="front_left_wheel" type="fixed">
		<parent link="chassis_link"/>
		<child link="front_left_wheel_link"/>
		<origin rpy="0 0 0" xyz="0.131 0.187795 0.0345"/>
		<axis xyz="0 1 0"/>
	</joint>

	<link name="front_right_wheel_link">
		<visual>
			<origin rpy="1.57079632679 0 0" xyz="0 0 0"/>
			<geometry>
				<mesh filename="meshes/jackal-wheel.stl"/>
			</geometry>
			<material name="black"/>
		</visual>
	</link>

	<joint name="front_rignt_wheel" type="fixed">
		<parent link="chassis_link"/>
		<child link="front_right_wheel_link"/>
		<origin rpy="0 0 0" xyz="0.131 -0.187795 0.0345"/>
		<axis xyz="0 1 0"/>
	</joint>

	<link name="rear_left_wheel_link">
		<visual>
			<origin rpy="1.57079632679 0 0" xyz="0 0 0"/>
			<geometry>
				<mesh filename="meshes/jackal-wheel.stl"/>
			</geometry>
			<material name="black"/>
		</visual>
	</link>

	<joint name="rear_left_wheel" type="fixed">
		<parent link="chassis_link"/>
		<child link="rear_left_wheel_link"/>
		<origin rpy="0 0 0" xyz="-0.131 0.187795 0.0345"/>
		<axis xyz="0 1 0"/>
	</joint>

	<link name="rear_right_wheel_link">
		<visual>
			<origin rpy="1.57079632679 0 0" xyz="0 0 0"/>
			<geometry>
				<mesh filename="meshes/jackal-wheel.stl"/>
			</geometry>
			<material name="black"/>
		</visual>
	</link>

	<joint name="rear_right_wheel" type="fixed">
		<parent link="chassis_link"/>
		<child link="rear_right_wheel_link"/>
		<origin rpy="0 0 0" xyz="-0.131 -0.187795 0.0345"/>
		<axis xyz="0 1 0"/>
	</joint>

	<link name="front_fender_link">
		<visual>
			<geometry>
				<mesh filename="meshes/jackal-fender.stl"/>
			</geometry>
			<material name="yellow"/>
		</visual>
	</link>

	<joint name="front_fender_joint" type="fixed">
		<origin rpy="0 0 0" xyz="0 0 0"/>
		<parent link="chassis_link"/>
		<child link="front_fender_link"/>
	</joint>

	<link name="rear_fender_link">
		<visual>
			<geometry>
				<mesh filename="meshes/jackal-fender.stl"/>
			</geometry>
			<material name="yellow"/>
		</visual>
	</link>

	<joint name="rear_fender_joint" type="fixed">
		<origin rpy="0 0 3.14159265359" xyz="0 0 0"/>
		<parent link="chassis_link"/>
		<child link="rear_fender_link"/>
	</joint>

	<link name="left_wheel_link">
		<collision>
			<origin rpy="1.57079632679 0 0" xyz="0 0 0"/>
			<geometry>
				<cylinder length="0.04" radius="0.098"/>
			</geometry>
		</collision>

		<inertial>
			<origin rpy="0 0 0" xyz="0 0 0"/>
			<mass value="0.477"/>
			<inertia ixx="0.0013" ixy="0" ixz="0" iyy="0.0024" iyz="0" izz="0.0013"/>
		</inertial>
	</link>

	<joint name="left_wheel" type="continuous">
		<parent link="chassis_link"/>
		<child link="left_wheel_link"/>
		<origin rpy="0 0 0" xyz="0.0 0.187795 0.0345"/>
		<axis xyz="0 1 0"/>
	</joint>

	<link name="right_wheel_link">
		<collision>
			<origin rpy="1.57079632679 0 0" xyz="0 0 0"/>
			<geometry>
				<cylinder length="0.04" radius="0.098"/>
			</geometry>
		</collision>
		<inertial>
			<origin rpy="0 0 0" xyz="0 0 0"/>
			<mass value="0.477"/>
			<inertia ixx="0.0013" ixy="0" ixz="0" iyy="0.0024" iyz="0" izz="0.0013"/>
		</inertial>
	</link>

	<joint name="right_wheel" type="continuous">
		<parent link="chassis_link"/>
		<child link="right_wheel_link"/>
		<origin rpy="0 0 0" xyz="0.0 -0.187795 0.0345"/>
		<axis xyz="0 1 0"/>
	</joint>

	<!-- <link name="front_ball1">
	</link>

	<joint name="front_ball_joint1" type="continuous">
		<parent link="chassis_link"/>
		<child link="front_ball1"/>
		<origin rpy="0 0 0" xyz="0.131 0 -0.0155"/>
		<axis xyz="1 0 0"/>
	</joint>

	<link name="front_ball2">
	</link>

	<joint name="front_ball_joint2" type="continuous">
		<parent link="front_ball1"/>
		<child link="front_ball2"/>
		<origin rpy="0 0 0" xyz="0.0 0 0.0"/>
		<axis xyz="0 1 0"/>
	</joint>

	<link name="front_ball3">
		<collision>
			<geometry>
				<sphere radius="0.048"/>
			</geometry>
		</collision>
	</link>

	<joint name="front_ball_joint3" type="continuous">
		<parent link="front_ball2"/>
		<child link="front_ball3"/>
		<origin rpy="0 0 0" xyz="0.0 0.0 0.0"/>
		<axis xyz="0 0 1"/>
	</joint>

	<link name="rear_ball1">
	</link>

	<joint name="rear_ball_joint1" type="continuous">
		<parent link="chassis_link"/>
		<child link="rear_ball1"/>
		<origin rpy="0 0 0" xyz="-0.131 0 -0.0155"/>
		<axis xyz="1 0 0"/>
	</joint>

	<link name="rear_ball2">
	</link>

	<joint name="rear_ball_joint2" type="continuous">
		<parent link="rear_ball1"/>
		<child link="rear_ball2"/>
		<origin rpy="0 0 0" xyz="0.0 0 0.0"/>
		<axis xyz="0 1 0"/>
	</joint>

	<link name="rear_ball3">
		<collision>
			<geometry>
				<sphere radius="0.048"/>
			</geometry>
		</collision>
	</link>

	<joint name="rear_ball_joint3" type="continuous">
		<parent link="rear_ball2"/>
		<child link="rear_ball3"/>
		<origin rpy="0 0 0" xyz="0.0 0.0 0.0"/>
		<axis xyz="0 0 1"/>
	</joint> -->

	<link name="front_ball">
		<collision>
			<geometry>
				<!-- <sphere radius="0.048"/> -->
				<sphere radius="0.047"/>
			</geometry>
		</collision>
	</link>

	<joint name="front_ball_joint" type="fixed">
		<parent link="chassis_link"/>
		<child link="front_ball"/>
		<origin rpy="0 0 0" xyz="0.131 0 -0.0155"/>
		<axis xyz="0 1 0"/>
	</joint>

	<link name="rear_ball">
		<collision>
			<geometry>
				<!-- <sphere radius="0.048"/> -->
				<sphere radius="0.047"/>
			</geometry>
		</collision>
	</link>

	<joint name="rear_ball_joint" type="fixed">
		<parent link="chassis_link"/>
		<child link="rear_ball"/>
		<origin rpy="0 0 0" xyz="-0.131 0 -0.0155"/>
		<axis xyz="0 1 0"/>
	</joint>

</robot>
